File: StressStrainOfAl/GroupB_polycarb.txt
""
"Test Method","MTS Simplified Tensile Edited.msm"
"Sample I. D.","GroupB_polycarbonate.mss"
"Specimen Number","5"

"Load (N)","Time (min)","Extension (mm)","Stress (MPa)","Strain (mm/mm)"

75.389,0.003,-0.143,3.840,-0.003
78.476,0.005,-0.119,3.997,-0.003
77.827,0.007,-0.096,3.964,-0.002
80.070,0.008,-0.073,4.078,-0.002
80.508,0.010,-0.049,4.100,-0.001
80.600,0.012,-0.026,4.105,-0.001
80.691,0.013,-0.002,4.110,-0.000
81.312,0.015,0.021,4.141,0.000
82.162,0.017,0.044,4.184,0.001
82.849,0.018,0.068,4.219,0.002
84.526,0.020,0.091,4.305,0.002
86.761,0.022,0.115,4.419,0.003
95.510,0.023,0.137,4.864,0.003
111.924,0.025,0.161,5.700,0.004
128.841,0.027,0.184,6.562,0.004
145.780,0.028,0.207,7.425,0.005
163.041,0.030,0.231,8.304,0.005
180.328,0.032,0.254,9.184,0.006
197.410,0.033,0.278,10.054,0.006
214.844,0.035,0.301,10.942,0.007
231.556,0.037,0.324,11.793,0.007
248.809,0.038,0.348,12.672,0.008
265.591,0.040,0.371,13.526,0.008
282.556,0.042,0.394,14.390,0.009
299.407,0.043,0.417,15.249,0.009
315.999,0.045,0.441,16.094,0.010
332.909,0.047,0.464,16.955,0.010
349.226,0.048,0.487,17.786,0.011
366.002,0.050,0.511,18.640,0.011
382.452,0.052,0.534,19.478,0.012
398.757,0.053,0.557,20.309,0.013
415.436,0.055,0.581,21.158,0.013
431.402,0.057,0.604,21.971,0.014
447.769,0.058,0.628,22.805,0.014
463.737,0.060,0.651,23.618,0.015
479.581,0.062,0.674,24.425,0.015
495.849,0.063,0.698,25.253,0.016
511.345,0.065,0.720,26.043,0.016
527.602,0.067,0.744,26.871,0.017
543.157,0.068,0.767,27.663,0.017
558.751,0.070,0.790,28.457,0.018
574.709,0.072,0.814,29.270,0.018
590.098,0.073,0.837,30.053,0.019
605.883,0.075,0.861,30.857,0.019
621.185,0.077,0.884,31.637,0.020
636.408,0.078,0.907,32.412,0.020
652.030,0.080,0.930,33.208,0.021
666.890,0.082,0.954,33.964,0.021
682.241,0.083,0.977,34.746,0.022
697.319,0.085,1.000,35.514,0.022
712.484,0.087,1.024,36.287,0.023
727.607,0.088,1.047,37.057,0.024
742.094,0.090,1.070,37.795,0.024
757.625,0.092,1.094,38.586,0.025
771.984,0.093,1.117,39.317,0.025
786.930,0.095,1.141,40.078,0.026
801.448,0.097,1.164,40.817,0.026
815.749,0.098,1.187,41.546,0.027
830.610,0.100,1.210,42.303,0.027
844.740,0.102,1.233,43.022,0.028
859.191,0.103,1.257,43.758,0.028
873.724,0.105,1.280,44.498,0.029
887.763,0.107,1.304,45.213,0.029
902.196,0.108,1.327,45.948,0.030
916.011,0.110,1.350,46.652,0.030
929.974,0.112,1.374,47.363,0.031
944.253,0.113,1.397,48.090,0.031
957.810,0.115,1.420,48.781,0.032
971.986,0.117,1.444,49.503,0.032
985.286,0.118,1.467,50.180,0.033
999.194,0.120,1.490,50.889,0.033
1012.554,0.122,1.513,51.569,0.034
1026.068,0.123,1.537,52.257,0.035
1039.812,0.125,1.560,52.957,0.035
1052.961,0.127,1.583,53.627,0.036
1066.402,0.128,1.607,54.311,0.036
1079.906,0.130,1.630,54.999,0.037
1092.541,0.132,1.653,55.643,0.037
1105.825,0.133,1.677,56.319,0.038
1118.611,0.135,1.700,56.970,0.038
1131.588,0.137,1.723,57.631,0.039
1144.646,0.138,1.747,58.296,0.039
1157.159,0.140,1.770,58.934,0.040
1170.215,0.142,1.794,59.599,0.040
1182.572,0.143,1.817,60.228,0.041
1195.313,0.145,1.840,60.877,0.041
1207.796,0.147,1.863,61.513,0.042
1220.165,0.148,1.887,62.142,0.042
1232.716,0.150,1.910,62.782,0.043
1244.766,0.152,1.933,63.395,0.043
1257.282,0.153,1.957,64.033,0.044
1269.368,0.155,1.980,64.648,0.044
1280.997,0.157,2.003,65.241,0.045
1293.110,0.158,2.027,65.858,0.046
1304.614,0.160,2.050,66.443,0.046
1316.575,0.162,2.073,67.053,0.047
1328.410,0.163,2.097,67.655,0.047
1339.907,0.165,2.120,68.241,0.048
1351.927,0.167,2.144,68.853,0.048
1363.039,0.168,2.167,69.419,0.049
1374.671,0.170,2.191,70.011,0.049
1385.808,0.172,2.213,70.579,0.050
1396.844,0.173,2.237,71.141,0.050
1408.229,0.175,2.260,71.721,0.051
1419.012,0.177,2.283,72.270,0.051
1430.295,0.178,2.307,72.844,0.052
1440.899,0.180,2.330,73.384,0.052
1451.670,0.182,2.353,73.933,0.053
1462.648,0.183,2.377,74.492,0.053
1473.049,0.185,2.400,75.022,0.054
1484.171,0.187,2.424,75.588,0.054
1494.477,0.188,2.447,76.113,0.055
1504.862,0.190,2.470,76.642,0.056
1515.420,0.192,2.493,77.180,0.056
1525.159,0.193,2.517,77.676,0.057
1535.743,0.195,2.540,78.215,0.057
1545.502,0.197,2.563,78.712,0.058
1555.748,0.198,2.587,79.234,0.058
1565.645,0.200,2.610,79.738,0.059
1575.330,0.202,2.633,80.231,0.059
1585.397,0.203,2.657,80.744,0.060
1594.862,0.205,2.680,81.226,0.060
1604.652,0.207,2.703,81.724,0.061
1614.156,0.208,2.726,82.208,0.061
1623.651,0.210,2.750,82.692,0.062
1633.192,0.212,2.773,83.178,0.062
1642.238,0.213,2.796,83.638,0.063
1651.759,0.215,2.820,84.123,0.063
1660.575,0.217,2.843,84.572,0.064
1669.679,0.218,2.867,85.036,0.064
1678.928,0.220,2.890,85.507,0.065
1687.688,0.222,2.913,85.953,0.065
1696.851,0.223,2.937,86.420,0.066
1705.474,0.225,2.960,86.859,0.067
1714.180,0.227,2.983,87.302,0.067
1722.960,0.228,3.006,87.750,0.068
1731.277,0.230,3.030,88.173,0.068
1739.956,0.232,3.053,88.615,0.069
1748.083,0.233,3.076,89.029,0.069
1756.558,0.235,3.100,89.461,0.070
1764.889,0.237,3.123,89.885,0.070
1772.913,0.238,3.146,90.294,0.071
1781.195,0.240,3.170,90.716,0.071
1789.042,0.242,3.193,91.115,0.072
1797.145,0.243,3.217,91.528,0.072
1805.095,0.245,3.239,91.933,0.073
1812.779,0.247,3.263,92.324,0.073
1820.764,0.248,3.287,92.731,0.074
1828.019,0.250,3.309,93.100,0.074
1835.931,0.252,3.333,93.503,0.075
1843.324,0.253,3.356,93.880,0.075
1850.859,0.255,3.380,94.263,0.076
1858.355,0.257,3.403,94.645,0.076
1865.548,0.258,3.426,95.012,0.077
1873.012,0.260,3.450,95.392,0.078
1880.076,0.262,3.473,95.751,0.078
1887.207,0.263,3.497,96.115,0.079
1894.279,0.265,3.520,96.475,0.079
1901.154,0.267,3.543,96.825,0.080
1908.303,0.268,3.566,97.189,0.080
1915.098,0.270,3.589,97.535,0.081
1921.775,0.272,3.613,97.875,0.081
1928.652,0.273,3.636,98.225,0.082
1935.085,0.275,3.659,98.553,0.082
1942.168,0.277,3.683,98.914,0.083
1948.369,0.278,3.706,99.230,0.083
1954.881,0.280,3.730,99.561,0.084
1961.505,0.282,3.753,99.899,0.084
1967.567,0.283,3.776,100.207,0.085
1974.074,0.285,3.800,100.539,0.085
1980.041,0.287,3.823,100.843,0.086
1986.246,0.288,3.846,101.159,0.086
1992.530,0.290,3.869,101.479,0.087
1998.434,0.292,3.893,101.779,0.087
2004.804,0.293,3.916,102.104,0.088
2010.447,0.295,3.939,102.391,0.089
2016.467,0.297,3.963,102.698,0.089
2022.378,0.298,3.986,102.999,0.090
2027.715,0.300,4.010,103.271,0.090
2033.703,0.302,4.033,103.576,0.091
2038.988,0.303,4.056,103.845,0.091
2044.712,0.305,4.079,104.136,0.092
2050.428,0.307,4.103,104.427,0.092
2055.689,0.308,4.126,104.695,0.093
2061.431,0.310,4.150,104.988,0.093
2066.615,0.312,4.173,105.252,0.094
2071.966,0.313,4.196,105.524,0.094
2077.349,0.315,4.220,105.799,0.095
2082.187,0.317,4.243,106.045,0.095
2087.669,0.318,4.267,106.324,0.096
2092.593,0.320,4.289,106.575,0.096
2097.725,0.322,4.313,106.836,0.097
2102.898,0.323,4.337,107.100,0.097
2107.599,0.325,4.360,107.339,0.098
2112.511,0.327,4.383,107.589,0.099
2116.980,0.328,4.406,107.817,0.099
2121.667,0.330,4.429,108.056,0.100
2126.590,0.332,4.453,108.306,0.100
2131.123,0.333,4.476,108.537,0.101
2135.916,0.335,4.500,108.781,0.101
2140.474,0.337,4.523,109.013,0.102
2144.923,0.338,4.547,109.240,0.102
2149.457,0.340,4.570,109.471,0.103
2153.615,0.342,4.593,109.683,0.103
2158.213,0.343,4.617,109.917,0.104
2162.079,0.345,4.639,110.114,0.104
2166.568,0.347,4.663,110.342,0.105
2170.635,0.348,4.686,110.550,0.105
2174.607,0.350,4.709,110.752,0.106
2178.835,0.352,4.733,110.967,0.106
2182.611,0.353,4.756,111.159,0.107
2186.793,0.355,4.780,111.372,0.107
2190.700,0.357,4.803,111.571,0.108
2194.389,0.358,4.826,111.759,0.108
2198.233,0.360,4.850,111.955,0.109
2201.840,0.362,4.873,112.139,0.110
2205.696,0.363,4.896,112.335,0.110
2209.010,0.365,4.919,112.504,0.111
2212.806,0.367,4.943,112.697,0.111
2216.264,0.368,4.966,112.873,0.112
2219.476,0.370,4.989,113.037,0.112
2223.032,0.372,5.013,113.218,0.113
2226.227,0.373,5.036,113.381,0.113
2229.574,0.375,5.060,113.551,0.114
2232.838,0.377,5.083,113.718,0.114
2235.731,0.378,5.106,113.865,0.115
2238.912,0.380,5.129,114.027,0.115
2241.620,0.382,5.152,114.165,0.116
2244.793,0.383,5.176,114.326,0.116
2247.682,0.385,5.199,114.474,0.117
2250.374,0.387,5.223,114.611,0.117
2253.376,0.388,5.246,114.764,0.118
2255.834,0.390,5.269,114.889,0.118
2258.678,0.392,5.293,115.034,0.119
2261.147,0.393,5.316,115.159,0.119
2263.577,0.395,5.340,115.283,0.120
2266.106,0.397,5.363,115.412,0.121
2268.095,0.398,5.386,115.513,0.121
2270.530,0.400,5.410,115.637,0.122
2272.399,0.402,5.433,115.732,0.122
2274.341,0.403,5.456,115.831,0.123
2276.530,0.405,5.480,115.943,0.123
2278.068,0.407,5.503,116.021,0.124
2279.912,0.408,5.526,116.115,0.124
2281.097,0.410,5.549,116.175,0.125
2282.560,0.412,5.573,116.250,0.125
2283.949,0.413,5.596,116.321,0.126
2284.611,0.415,5.619,116.354,0.126
2285.484,0.417,5.643,116.399,0.127
2285.756,0.418,5.666,116.413,0.127
2285.829,0.420,5.689,116.416,0.128
2285.637,0.422,5.713,116.407,0.128
2284.358,0.423,5.736,116.341,0.129
2282.771,0.425,5.759,116.261,0.129
2279.753,0.427,5.782,116.107,0.130
2275.523,0.428,5.806,115.891,0.130
2269.361,0.430,5.829,115.578,0.131
2260.115,0.432,5.853,115.107,0.132
2247.073,0.433,5.876,114.442,0.132
2226.525,0.435,5.899,113.396,0.133
2191.923,0.437,5.923,111.634,0.133
2103.583,0.438,5.946,107.135,0.134
2019.437,0.440,5.969,102.849,0.134
1978.629,0.442,5.993,100.771,0.135
1955.615,0.443,6.016,99.599,0.135
1941.959,0.445,6.040,98.903,0.136
1932.808,0.447,6.063,98.437,0.136
1926.342,0.448,6.086,98.108,0.137
1922.001,0.450,6.110,97.887,0.137
1918.132,0.452,6.133,97.690,0.138
1915.990,0.453,6.157,97.581,0.138
1914.023,0.455,6.179,97.480,0.139
1912.821,0.457,6.203,97.419,0.139
1911.736,0.458,6.226,97.364,0.140
1910.504,0.460,6.249,97.301,0.140
1910.058,0.462,6.273,97.278,0.141
1909.136,0.463,6.296,97.231,0.141
1908.852,0.465,6.320,97.217,0.142
1908.516,0.467,6.343,97.200,0.143
1907.699,0.468,6.366,97.158,0.143
1907.152,0.470,6.390,97.130,0.144
1906.136,0.472,6.413,97.079,0.144
1905.278,0.473,6.436,97.035,0.145
1904.389,0.475,6.460,96.990,0.145
1902.811,0.477,6.483,96.909,0.146
1901.974,0.478,6.506,96.867,0.146
1900.438,0.480,6.529,96.789,0.147
1898.912,0.482,6.553,96.711,0.147
1897.485,0.483,6.576,96.638,0.148
1895.415,0.485,6.599,96.533,0.148
1893.651,0.487,6.623,96.443,0.149
1891.518,0.488,6.646,96.334,0.149
1889.233,0.490,6.670,96.218,0.150
1887.040,0.492,6.693,96.106,0.150
1884.318,0.493,6.716,95.968,0.151
1882.129,0.495,6.740,95.856,0.151
1879.113,0.497,6.763,95.702,0.152
1876.307,0.498,6.786,95.560,0.153
1873.667,0.500,6.810,95.425,0.153
1870.545,0.502,6.833,95.266,0.154
1867.785,0.503,6.856,95.126,0.154
1864.765,0.505,6.879,94.972,0.155
1861.998,0.507,6.903,94.831,0.155
1859.093,0.508,6.927,94.683,0.156
1855.865,0.510,6.950,94.518,0.156
1853.189,0.512,6.974,94.382,0.157
1849.872,0.513,6.996,94.213,0.157
1846.970,0.515,7.020,94.065,0.158
1844.509,0.517,7.043,93.940,0.158
1841.645,0.518,7.066,93.794,0.159
1839.283,0.520,7.090,93.674,0.159
1836.429,0.522,7.113,93.529,0.160
1834.344,0.523,7.137,93.422,0.160
1832.074,0.525,7.160,93.307,0.161
1829.857,0.527,7.183,93.194,0.161
1828.381,0.528,7.207,93.119,0.162
1826.106,0.530,7.230,93.003,0.162
1824.257,0.532,7.253,92.909,0.163
1822.562,0.533,7.276,92.822,0.164
1820.825,0.535,7.300,92.734,0.164
1819.530,0.537,7.323,92.668,0.165
1818.047,0.538,7.346,92.592,0.165
1817.301,0.540,7.370,92.554,0.166
1815.926,0.542,7.393,92.484,0.166
1814.955,0.543,7.416,92.435,0.167
1814.376,0.545,7.440,92.405,0.167
1813.391,0.547,7.463,92.355,0.168
1812.908,0.548,7.487,92.331,0.168
1812.084,0.550,7.509,92.289,0.169
1811.533,0.552,7.533,92.261,0.169
1811.170,0.553,7.556,92.242,0.170
1810.487,0.555,7.580,92.207,0.170
1810.679,0.557,7.603,92.217,0.171
1810.016,0.558,7.626,92.183,0.171
1810.110,0.560,7.650,92.188,0.172
1809.884,0.562,7.673,92.177,0.172
1809.764,0.563,7.696,92.171,0.173
1810.031,0.565,7.720,92.184,0.173
1809.555,0.567,7.743,92.160,0.174
1809.850,0.568,7.767,92.175,0.175
1809.815,0.570,7.790,92.173,0.175
1809.833,0.572,7.813,92.174,0.176
1810.114,0.573,7.837,92.188,0.176
1809.837,0.575,7.860,92.174,0.177
1810.109,0.577,7.883,92.188,0.177
1810.157,0.578,7.906,92.191,0.178
1810.187,0.580,7.930,92.192,0.178
1810.643,0.582,7.953,92.215,0.179
1810.416,0.583,7.976,92.204,0.179
1810.915,0.585,8.000,92.229,0.180
1810.834,0.587,8.023,92.225,0.180
1810.961,0.588,8.046,92.231,0.181
1811.351,0.590,8.070,92.251,0.181
1811.133,0.592,8.093,92.240,0.182
1811.530,0.593,8.117,92.260,0.182
1811.228,0.595,8.139,92.245,0.183
1811.466,0.597,8.163,92.257,0.183
1811.889,0.598,8.186,92.279,0.184
1811.767,0.600,8.210,92.273,0.184
1812.404,0.602,8.233,92.305,0.185
1812.554,0.603,8.256,92.313,0.186
1812.708,0.605,8.280,92.320,0.186
1812.965,0.607,8.303,92.334,0.187
1813.028,0.608,8.326,92.337,0.187
1813.614,0.610,8.350,92.367,0.188
1813.758,0.612,8.373,92.374,0.188
1814.270,0.613,8.396,92.400,0.189
1814.574,0.615,8.420,92.415,0.189
1814.711,0.617,8.443,92.422,0.190
1815.555,0.618,8.467,92.465,0.190
1815.733,0.620,8.490,92.475,0.191
1816.083,0.622,8.513,92.492,0.191
1816.566,0.623,8.536,92.517,0.192
1816.750,0.625,8.560,92.526,0.192
1817.399,0.627,8.583,92.559,0.193
1817.682,0.628,8.606,92.574,0.193
1818.187,0.630,8.630,92.600,0.194
1818.351,0.632,8.653,92.608,0.194
1818.649,0.633,8.676,92.623,0.195
1819.194,0.635,8.700,92.651,0.195
1819.312,0.637,8.723,92.657,0.196
1819.908,0.638,8.747,92.687,0.197
1820.507,0.640,8.770,92.718,0.197
1820.434,0.642,8.793,92.714,0.198
1821.084,0.643,8.817,92.747,0.198
1821.163,0.645,8.839,92.751,0.199
1821.511,0.647,8.863,92.769,0.199
1821.556,0.648,8.886,92.771,0.200
1821.860,0.650,8.909,92.787,0.200
1822.457,0.652,8.933,92.817,0.201
1822.270,0.653,8.956,92.807,0.201
1822.609,0.655,8.980,92.825,0.202
1822.951,0.657,9.003,92.842,0.202
1823.010,0.658,9.026,92.845,0.203
1823.349,0.660,9.050,92.862,0.203
1823.390,0.662,9.073,92.865,0.204
1823.893,0.663,9.097,92.890,0.204
1824.026,0.665,9.120,92.897,0.205
1823.999,0.667,9.143,92.895,0.205
1824.302,0.668,9.167,92.911,0.206
1823.944,0.670,9.189,92.893,0.207
1824.324,0.672,9.213,92.912,0.207
1824.319,0.673,9.236,92.912,0.208
1824.481,0.675,9.260,92.920,0.208
1824.910,0.677,9.283,92.942,0.209
1824.868,0.678,9.306,92.940,0.209
1825.297,0.680,9.330,92.962,0.210
1825.253,0.682,9.353,92.959,0.210
1825.254,0.683,9.377,92.959,0.211
1825.528,0.685,9.400,92.973,0.211
1825.271,0.687,9.423,92.960,0.212
1825.585,0.688,9.447,92.976,0.212
1825.402,0.690,9.469,92.967,0.213
1825.545,0.692,9.493,92.974,0.213
1825.613,0.693,9.516,92.978,0.214
1825.646,0.695,9.539,92.979,0.214
1826.021,0.697,9.563,92.999,0.215
1825.705,0.698,9.586,92.982,0.215
1825.968,0.700,9.610,92.996,0.216
1825.926,0.702,9.633,92.994,0.216
1825.887,0.703,9.656,92.992,0.217
1825.910,0.705,9.680,92.993,0.218
1825.784,0.707,9.703,92.986,0.218
1825.962,0.708,9.727,92.995,0.219
1825.833,0.710,9.749,92.989,0.219
1825.632,0.712,9.773,92.979,0.220
1825.970,0.713,9.797,92.996,0.220
1825.792,0.715,9.820,92.987,0.221
1825.998,0.717,9.843,92.997,0.221
1825.841,0.718,9.866,92.989,0.222
1825.691,0.720,9.890,92.982,0.222
1826.008,0.722,9.913,92.998,0.223
1825.776,0.723,9.936,92.986,0.223
1826.049,0.725,9.960,93.000,0.224
1825.866,0.727,9.983,92.991,0.224
1825.799,0.728,10.006,92.987,0.225
1825.951,0.730,10.030,92.995,0.225
1825.908,0.732,10.053,92.993,0.226
1826.241,0.733,10.077,93.010,0.226
1826.077,0.735,10.100,93.001,0.227
1826.194,0.737,10.123,93.007,0.227
1826.083,0.738,10.146,93.002,0.228
1825.977,0.740,10.170,92.996,0.229
1826.425,0.742,10.193,93.019,0.229
1826.058,0.743,10.216,93.000,0.230
1826.186,0.745,10.240,93.007,0.230
1826.309,0.747,10.263,93.013,0.231
1826.048,0.748,10.286,93.000,0.231
1826.273,0.750,10.310,93.011,0.232
1826.039,0.752,10.333,92.999,0.232
1826.324,0.753,10.357,93.014,0.233
1826.522,0.755,10.380,93.024,0.233
1826.257,0.757,10.403,93.010,0.234
1826.606,0.758,10.426,93.028,0.234
1826.488,0.760,10.449,93.022,0.235
1826.583,0.762,10.473,93.027,0.235
1826.534,0.763,10.496,93.025,0.236
1826.316,0.765,10.520,93.013,0.236
1826.665,0.767,10.543,93.031,0.237
1826.272,0.768,10.566,93.011,0.237
1826.447,0.770,10.590,93.020,0.238
1826.417,0.772,10.613,93.019,0.238
1826.411,0.773,10.636,93.018,0.239
1826.822,0.775,10.660,93.039,0.240
1826.396,0.777,10.683,93.018,0.240
1826.484,0.778,10.707,93.022,0.241
1826.470,0.780,10.729,93.021,0.241
1826.333,0.782,10.753,93.014,0.242
1826.713,0.783,10.776,93.034,0.242
1826.425,0.785,10.799,93.019,0.243
1826.785,0.787,10.823,93.037,0.243
1826.626,0.788,10.846,93.029,0.244
1826.683,0.790,10.870,93.032,0.244
1826.955,0.792,10.893,93.046,0.245
1826.707,0.793,10.916,93.033,0.245
1827.010,0.795,10.940,93.049,0.246
1826.908,0.797,10.963,93.044,0.246
1827.052,0.798,10.987,93.051,0.247
1827.160,0.800,11.010,93.056,0.247
1827.064,0.802,11.033,93.052,0.248
1827.478,0.803,11.057,93.073,0.248
1827.193,0.805,11.079,93.058,0.249
1827.536,0.807,11.103,93.076,0.250
1827.745,0.808,11.126,93.086,0.250
1827.653,0.810,11.150,93.082,0.251
1828.090,0.812,11.173,93.104,0.251
1828.018,0.813,11.196,93.100,0.252
1828.108,0.815,11.220,93.105,0.252
1828.391,0.817,11.243,93.119,0.253
1828.334,0.818,11.266,93.116,0.253
1828.814,0.820,11.290,93.141,0.254
1828.519,0.822,11.313,93.126,0.254
1828.957,0.823,11.336,93.148,0.255
1829.223,0.825,11.359,93.162,0.255
1829.242,0.827,11.383,93.163,0.256
1829.589,0.828,11.407,93.180,0.256
1829.520,0.830,11.429,93.177,0.257
1829.624,0.832,11.453,93.182,0.257
1829.996,0.833,11.476,93.201,0.258
1829.817,0.835,11.500,93.192,0.258
1830.520,0.837,11.524,93.228,0.259
1830.136,0.838,11.546,93.208,0.259
1830.197,0.840,11.570,93.211,0.260
1830.237,0.842,11.593,93.213,0.261
1830.247,0.843,11.616,93.214,0.261
1830.630,0.845,11.640,93.233,0.262
1830.521,0.847,11.663,93.228,0.262
1830.885,0.848,11.687,93.246,0.263
1831.081,0.850,11.710,93.256,0.263
1831.033,0.852,11.733,93.254,0.264
1831.406,0.853,11.757,93.273,0.264
1831.322,0.855,11.780,93.268,0.265
1831.488,0.857,11.803,93.277,0.265
1831.525,0.858,11.826,93.279,0.266
1831.456,0.860,11.850,93.275,0.266
1831.876,0.862,11.873,93.297,0.267
1831.484,0.863,11.896,93.277,0.267
1831.901,0.865,11.920,93.298,0.268
1831.840,0.867,11.943,93.295,0.268
1831.992,0.868,11.966,93.303,0.269
1832.179,0.870,11.990,93.312,0.269
1831.931,0.872,12.013,93.299,0.270
1832.201,0.873,12.037,93.313,0.270
1832.191,0.875,12.059,93.313,0.271
1832.199,0.877,12.083,93.313,0.272
1832.338,0.878,12.106,93.320,0.272
1832.234,0.880,12.130,93.315,0.273
1832.506,0.882,12.153,93.329,0.273
1832.275,0.883,12.176,93.317,0.274
1832.431,0.885,12.200,93.325,0.274
1832.616,0.887,12.223,93.334,0.275
1832.550,0.888,12.246,93.331,0.275
1832.825,0.890,12.270,93.345,0.276
1832.435,0.892,12.293,93.325,0.276
1832.704,0.893,12.317,93.339,0.277
1832.550,0.895,12.339,93.331,0.277
1832.579,0.897,12.363,93.333,0.278
1832.902,0.898,12.386,93.349,0.278
1832.816,0.900,12.409,93.345,0.279
1832.931,0.902,12.433,93.350,0.279
1833.010,0.903,12.456,93.354,0.280
1832.959,0.905,12.480,93.352,0.280
1832.960,0.907,12.503,93.352,0.281
1832.812,0.908,12.526,93.344,0.281
1833.096,0.910,12.550,93.359,0.282
1833.043,0.912,12.573,93.356,0.283
1833.016,0.913,12.596,93.355,0.283
1833.334,0.915,12.620,93.371,0.284
1833.130,0.917,12.643,93.361,0.284
1833.431,0.918,12.667,93.376,0.285
1833.343,0.920,12.689,93.371,0.285
1833.406,0.922,12.713,93.375,0.286
1833.461,0.923,12.736,93.377,0.286
1833.373,0.925,12.759,93.373,0.287
1833.893,0.927,12.783,93.399,0.287
1833.532,0.928,12.806,93.381,0.288
1833.817,0.930,12.830,93.396,0.288
1834.126,0.932,12.853,93.411,0.289
1834.024,0.933,12.876,93.406,0.289
1834.283,0.935,12.900,93.419,0.290
1834.201,0.937,12.923,93.415,0.290
1834.691,0.938,12.946,93.440,0.291
1834.754,0.940,12.969,93.443,0.291
1834.768,0.942,12.993,93.444,0.292
1835.143,0.943,13.017,93.463,0.293
1835.163,0.945,13.040,93.464,0.293
1835.468,0.947,13.063,93.480,0.294
1835.541,0.948,13.086,93.483,0.294
1835.493,0.950,13.110,93.481,0.295
1835.811,0.952,13.133,93.497,0.295
1835.719,0.953,13.156,93.492,0.296
1836.177,0.955,13.180,93.516,0.296
1836.137,0.957,13.203,93.514,0.297
1836.310,0.958,13.226,93.523,0.297
1836.673,0.960,13.250,93.541,0.298
1836.548,0.962,13.273,93.535,0.298
1836.779,0.963,13.297,93.546,0.299
1836.752,0.965,13.319,93.545,0.299
1836.833,0.967,13.343,93.549,0.300
1836.850,0.968,13.366,93.550,0.300
1836.716,0.970,13.389,93.543,0.301
1837.123,0.972,13.413,93.564,0.301
1837.037,0.973,13.436,93.560,0.302
1837.023,0.975,13.460,93.559,0.302
1837.224,0.977,13.483,93.569,0.303
1836.925,0.978,13.506,93.554,0.304
1837.388,0.980,13.530,93.577,0.304
1837.107,0.982,13.553,93.563,0.305
1837.332,0.983,13.577,93.575,0.305
1837.319,0.985,13.600,93.574,0.306
1837.106,0.987,13.623,93.563,0.306
1837.372,0.988,13.646,93.577,0.307
1837.093,0.990,13.669,93.562,0.307
1837.320,0.992,13.693,93.574,0.308
1837.757,0.993,13.716,93.596,0.308
1837.459,0.995,13.739,93.581,0.309
1837.825,0.997,13.763,93.600,0.309
1837.889,0.998,13.786,93.603,0.310
1837.962,1.000,13.810,93.607,0.310
1838.197,1.002,13.833,93.619,0.311
1838.064,1.003,13.856,93.612,0.311
1838.564,1.005,13.880,93.637,0.312
1838.420,1.007,13.903,93.630,0.312
1838.571,1.008,13.927,93.638,0.313
1838.799,1.010,13.950,93.649,0.313
1838.272,1.012,13.973,93.622,0.314
1838.657,1.013,13.996,93.642,0.315
1838.644,1.015,14.019,93.641,0.315
1838.755,1.017,14.043,93.647,0.316
1839.045,1.018,14.066,93.662,0.316
1838.901,1.020,14.090,93.654,0.317
1839.338,1.022,14.114,93.677,0.317
1839.096,1.023,14.136,93.664,0.318
1839.163,1.025,14.160,93.668,0.318
1839.332,1.027,14.183,93.676,0.319
1838.782,1.028,14.206,93.648,0.319
1839.258,1.030,14.230,93.673,0.320
1839.011,1.032,14.253,93.660,0.320
1839.238,1.033,14.276,93.672,0.321
1839.128,1.035,14.299,93.666,0.321
1839.166,1.037,14.323,93.668,0.322
1839.374,1.038,14.347,93.679,0.322
1839.295,1.040,14.370,93.675,0.323
1839.484,1.042,14.393,93.684,0.323
1839.371,1.043,14.416,93.678,0.324
1839.398,1.045,14.440,93.680,0.324
1839.493,1.047,14.463,93.685,0.325
1839.177,1.048,14.486,93.669,0.326
1839.507,1.050,14.510,93.685,0.326
1839.363,1.052,14.533,93.678,0.327
1839.582,1.053,14.556,93.689,0.327
1839.836,1.055,14.580,93.702,0.328
1839.723,1.057,14.603,93.696,0.328
1840.153,1.058,14.627,93.718,0.329
1839.944,1.060,14.650,93.708,0.329
1840.118,1.062,14.673,93.716,0.330
1840.287,1.063,14.696,93.725,0.330
1840.160,1.065,14.719,93.719,0.331
1840.570,1.067,14.743,93.739,0.331
1840.517,1.068,14.766,93.737,0.332
1840.805,1.070,14.790,93.751,0.332
1840.954,1.072,14.813,93.759,0.333
1840.964,1.073,14.836,93.760,0.333
1841.441,1.075,14.860,93.784,0.334
1841.344,1.077,14.883,93.779,0.334
1841.735,1.078,14.907,93.799,0.335
1841.673,1.080,14.930,93.796,0.335
1841.816,1.082,14.953,93.803,0.336
1842.265,1.083,14.977,93.826,0.337
1842.138,1.085,14.999,93.819,0.337
1842.428,1.087,15.023,93.834,0.338
1842.560,1.088,15.046,93.841,0.338
1842.584,1.090,15.070,93.842,0.339
1842.833,1.092,15.093,93.855,0.339
1842.782,1.093,15.116,93.852,0.340
1843.337,1.095,15.140,93.880,0.340
1843.212,1.097,15.163,93.874,0.341
1843.530,1.098,15.186,93.890,0.341
1843.740,1.100,15.210,93.901,0.342
1843.714,1.102,15.233,93.900,0.342
1843.985,1.103,15.257,93.913,0.343
1844.090,1.105,15.279,93.919,0.343
1844.188,1.107,15.303,93.924,0.344
1844.235,1.108,15.326,93.926,0.344
1844.328,1.110,15.350,93.931,0.345
1844.648,1.112,15.373,93.947,0.345
1844.647,1.113,15.396,93.947,0.346
1844.769,1.115,15.420,93.953,0.347
1844.968,1.117,15.443,93.963,0.347
1844.936,1.118,15.466,93.962,0.348
1845.157,1.120,15.490,93.973,0.348
1844.813,1.122,15.513,93.956,0.349
1844.963,1.123,15.537,93.963,0.349
1844.927,1.125,15.559,93.961,0.350
1844.995,1.127,15.583,93.965,0.350
1845.229,1.128,15.606,93.977,0.351
1844.855,1.130,15.629,93.958,0.351
1845.103,1.132,15.653,93.970,0.352
1845.097,1.133,15.676,93.970,0.352
1845.032,1.135,15.700,93.967,0.353
1845.132,1.137,15.723,93.972,0.353
1844.857,1.138,15.746,93.958,0.354
1845.123,1.140,15.770,93.971,0.354
1844.903,1.142,15.793,93.960,0.355
1844.793,1.143,15.816,93.955,0.355
1844.905,1.145,15.840,93.960,0.356
1844.691,1.147,15.863,93.949,0.356
1844.892,1.148,15.886,93.960,0.357
1844.777,1.150,15.909,93.954,0.358
1844.627,1.152,15.933,93.946,0.358
1844.760,1.153,15.956,93.953,0.359
1844.582,1.155,15.980,93.944,0.359
1844.668,1.157,16.003,93.948,0.360
1844.256,1.158,16.026,93.927,0.360
1844.224,1.160,16.049,93.926,0.361
1844.506,1.162,16.073,93.940,0.361
1844.048,1.163,16.096,93.917,0.362
1844.236,1.165,16.120,93.926,0.362
1844.136,1.167,16.143,93.921,0.363
1844.097,1.168,16.166,93.919,0.363
1844.245,1.170,16.190,93.927,0.364
1844.044,1.172,16.213,93.916,0.364
1844.175,1.173,16.237,93.923,0.365
1844.008,1.175,16.260,93.915,0.365
1843.882,1.177,16.283,93.908,0.366
1844.249,1.178,16.307,93.927,0.366
1843.675,1.180,16.330,93.898,0.367
1843.649,1.182,16.353,93.896,0.367
1842.801,1.183,16.376,93.853,0.368
1842.788,1.185,16.399,93.852,0.369
1842.810,1.187,16.423,93.854,0.369
1842.225,1.188,16.446,93.824,0.370
1842.100,1.190,16.470,93.817,0.370
1841.405,1.192,16.493,93.782,0.371
1840.691,1.193,16.517,93.746,0.371
1839.581,1.195,16.540,93.689,0.372
1837.839,1.197,16.563,93.600,0.372
1835.656,1.198,16.587,93.489,0.373
1831.951,1.200,16.609,93.300,0.373
1825.768,1.202,16.633,92.986,0.374
1812.039,1.203,16.656,92.286,0.374
1498.630,1.205,16.680,76.325,0.375
-149.394,1.205,16.683,-7.609,0.375