File: StressStrainOfAl/GroupB_uknown.csv
Test Method,MTS Tensile with Extensometer_edited.msm,,,,
Sample I. D.,GroupB_unknown metal,,,,
Specimen Number,2,,,Trial 1,
,,,,,
Load (N),Time (s),Extension (mm),Stress (MPa),Strain (mm/mm),Crosshead (mm)
,,,,,
-148.915,0.9,-0.354,-12.65799651,-0.006958915,
-146.554,1.7,-0.336,-12.457308,-0.006605072,
-143.843,2.5,-0.317,-12.22686897,-0.006231571,
-140.717,3.3,-0.299,-11.96115432,-0.005877728,
-137.669,4.1,-0.28,-11.70206979,-0.005504226,
-133.959,4.9,-0.262,-11.38671427,-0.005150383,
-129.993,5.7,-0.244,-11.04959837,-0.00479654,
-125.559,6.5,-0.224,-10.67270177,-0.004403381,
-120.603,7.3,-0.204,-10.2514344,-0.004010222,
-114.481,8.1,-0.184,-9.731055293,-0.003617063,
-107.404,8.9,-0.164,-9.129499766,-0.003223904,
-98.892,9.7,-0.146,-8.405967104,-0.002870061,
-88.385,10.5,-0.125,-7.512856475,-0.002457244,
-75.025,11.3,-0.103,-6.377236602,-0.002024769,
-57.12,12.1,-0.083,-4.855284967,-0.00163161,
-43.464,12.9,-0.07,-3.694504654,-0.001376057,
-42.115,13.7,-0.068,-3.579837647,-0.001336741,
-41.917,14.5,-0.067,-3.563007353,-0.001317083,
-41.739,15.3,-0.066,-3.547877088,-0.001297425,
-41.692,16.1,-0.067,-3.543882018,-0.001317083,
-41.648,16.9,-0.066,-3.540141952,-0.001297425,
-41.314,17.7,-0.066,-3.511751456,-0.001297425,
-41.014,18.5,-0.065,-3.486251009,-0.001277767,
-40.743,19.3,-0.065,-3.463215606,-0.001277767,
-40.685,20.1,-0.065,-3.45828552,-0.001277767,
-40.182,20.9,-0.065,-3.415529772,-0.001277767,
-39.522,21.7,-0.066,-3.35942879,-0.001297425,
-38.769,22.5,-0.065,-3.29542267,-0.001277767,
-25.112,23.3,-0.055,-2.134557355,-0.001081187,
6.131,24.1,-0.039,0.52114412,-0.00076666,
51.361,24.9,-0.022,4.365761401,-0.000432475,
55.766,25.7,-0.021,4.740192953,-0.000412817,
55.522,26.5,-0.02,4.71945259,-0.000393159,
55.35,27.3,-0.022,4.704832335,-0.000432475,
55.625,28.1,-0.021,4.728207744,-0.000412817,
55.727,28.9,-0.02,4.736877895,-0.000393159,
56.14,29.7,-0.019,4.77198351,-0.000373501,
56.437,30.5,-0.02,4.797228952,-0.000393159,
56.488,31.3,-0.02,4.801564027,-0.000393159,
56.659,32.1,-0.018,4.816099282,-0.000353843,
60.528,32.9,-0.018,5.144970037,-0.000353843,
94.977,33.7,-0.01,8.073186281,-0.00019658,
182.452,34.5,0.004,15.5086914,7.86E-05,
287.789,35.3,0.019,24.46249309,0.000373501,
403.717,36.1,0.031,34.31654554,0.000609397,
524.353,36.9,0.043,44.57078499,0.000845292,
644.522,37.7,0.055,54.78532874,0.001081187,
767.163,38.5,0.063,65.20999617,0.001238451,
889.938,39.3,0.075,75.64605381,0.001474346,
1011.283,40.1,0.085,85.96055931,0.001670926,
1132.759,40.9,0.095,96.28620001,0.001867505,
1250.745,41.7,0.105,106.3151855,0.002064085,
1368.25,42.5,0.116,116.3032853,0.002280322,
1483.332,43.3,0.127,126.0854265,0.00249656,
1594.137,44.1,0.137,135.5040163,0.002693139,
1697.778,44.9,0.149,144.3136555,0.002929035,
1774.506,45.7,0.162,150.8356496,0.003184588,
1803.748,46.5,0.179,153.3212631,0.003518773,
1811.021,47.3,0.193,153.9394789,0.003793985,
1812.03,48.1,0.209,154.0252454,0.004108512,
1815.483,48.9,0.228,154.3187556,0.004482013,
1817.622,49.7,0.247,154.5005738,0.004855514,
1821.892,50.5,0.266,154.8635301,0.005229015,
1827.851,51.3,0.287,155.370054,0.005641832,
1832.304,52.1,0.306,155.7485656,0.006015333,
1839.194,52.9,0.327,156.3342258,0.00642815,
1844.441,53.7,0.347,156.7802287,0.006821309,
1850.033,54.5,0.367,157.255557,0.007214468,
1856.778,55.3,0.386,157.828892,0.007587969,
1860.995,56.1,0.405,158.1873433,0.00796147,
1867.657,56.9,0.424,158.7536232,0.008334971,
1872.573,57.7,0.443,159.1714905,0.008708473,
1879.225,58.5,0.461,159.7369204,0.009062316,
1886.08,59.3,0.477,160.3196056,0.009376843,
1890.317,60.1,0.496,160.6797569,0.009750344,
1896.646,60.9,0.513,161.2177313,0.010084529,
1902.359,61.7,0.532,161.7033448,0.01045803,
1907.545,62.5,0.549,162.1441625,0.010792215,
1914.805,63.3,0.567,162.7612733,0.011146059,
1918.852,64.1,0.585,163.1052743,0.011499902,
1924.915,64.9,0.603,163.6206384,0.011853745,
1930.398,65.7,0.622,164.0867015,0.012227246,
1935.339,66.5,0.639,164.5066939,0.012561431,
1942.539,67.3,0.658,165.1187046,0.012934932,
1946.574,68.1,0.675,165.4616856,0.013269117,
1951.972,68.9,0.693,165.9205236,0.01362296,
1958.27,69.7,0.71,166.455863,0.013957146,
1962.576,70.5,0.729,166.8218794,0.014330647,
1968.874,71.3,0.746,167.3572188,0.014664832,
1973.204,72.1,0.764,167.7252752,0.015018675,
1978.351,72.9,0.781,168.1627778,0.01535286,
1984.563,73.7,0.798,168.6908071,0.015687045,
1988.92,74.5,0.816,169.0611586,0.016040889,
1994.588,75.3,0.833,169.542947,0.016375074,
1999.12,76.1,0.851,169.9281737,0.016728917,
2003.921,76.9,0.868,170.3362659,0.017063102,
2009.962,77.7,0.885,170.8497599,0.017397287,
2013.795,78.5,0.903,171.1755706,0.01775113,
2019.11,79.3,0.92,171.6273535,0.018085316,
2024.309,80.1,0.938,172.0692762,0.018439159,
2028.271,80.9,0.954,172.4060521,0.018753686,
2033.943,81.7,0.972,172.8881805,0.019107529,
2038.38,82.5,0.989,173.2653321,0.019441714,
2042.949,83.3,1.006,173.6537039,0.019775899,
2048.445,84.1,1.023,174.1208721,0.020110085,
2052.124,84.9,1.041,174.4335926,0.020463928,
2057.732,85.7,1.057,174.9102809,0.020778455,
2061.402,86.5,1.074,175.2222364,0.02111264,
2065.988,87.3,1.091,175.6120532,0.021446825,
2071.706,88.1,1.109,176.0980917,0.021800668,
2074.999,88.9,1.125,176.3780016,0.022115196,
2080.212,89.7,1.142,176.8211144,0.022449381,
2084.242,90.5,1.158,177.1636704,0.022763908,
2088.389,91.3,1.176,177.5161715,0.023117751,
2094.309,92.1,1.193,178.0193803,0.023451936,
2097.311,92.9,1.21,178.2745548,0.023786121,
2102.22,93.7,1.226,178.6918271,0.024100649,
2106.147,94.5,1.242,179.0256279,0.024415176,
2110.151,95.3,1.26,179.3659739,0.024769019,
2115.895,96.1,1.277,179.8542224,0.025103204,
2118.629,96.9,1.293,180.0866165,0.025417731,
2123.29,97.7,1.309,180.4828084,0.025732259,
2127.31,98.5,1.326,180.8245144,0.026066444,
2130.897,99.3,1.343,181.1294148,0.026400629,
2136.553,100.1,1.36,181.6101832,0.026734814,
2139.345,100.9,1.376,181.8475073,0.027049341,
2143.545,101.7,1.392,182.2045136,0.027363869,
2147.848,102.5,1.409,182.570275,0.027698054,
2151.116,103.3,1.427,182.8480598,0.028051897,
2156.996,104.1,1.443,183.3478686,0.028366424,
2159.122,104.9,1.46,183.5285818,0.028700609,
2163.43,105.7,1.476,183.8947682,0.029015137,
2167.789,106.5,1.491,184.2652896,0.029310006,
2170.652,107.3,1.509,184.5086489,0.029663849,
2176.061,108.1,1.525,184.9684219,0.029978376,
2178.379,108.9,1.542,185.1654554,0.030312561,
2182.478,109.7,1.559,185.5138765,0.030646747,
2186.981,110.5,1.574,185.8966382,0.030941616,
2189.718,111.3,1.59,186.1292873,0.031256143,
2195.086,112.1,1.607,186.5855752,0.031590328,
2197.271,112.9,1.623,186.7713035,0.031904856,
2200.964,113.7,1.639,187.085214,0.032219383,
2205.557,114.5,1.655,187.4756258,0.03253391,
2208.019,115.3,1.671,187.6848995,0.032848437,
2213.141,116.1,1.688,188.1202771,0.033182622,
2215.713,116.9,1.705,188.3389009,0.033516808,
2219.098,117.7,1.722,188.626631,0.033850993,
2223.654,118.5,1.737,189.0138977,0.034145862,
2225.628,119.3,1.753,189.1816907,0.034460389,
2230.905,120.1,1.77,189.6302435,0.034794574,
2233.513,120.9,1.786,189.8519274,0.035109102,
2236.572,121.7,1.802,190.111947,0.035423629,
2240.998,122.5,1.818,190.4881635,0.035738156,
2243.324,123.3,1.834,190.685877,0.036052683,
2248.068,124.1,1.851,191.0891241,0.036386868,
2250.584,124.9,1.867,191.3029878,0.036701396,
2253.517,125.7,1.883,191.5522972,0.037015923,
2258.313,126.5,1.9,191.9599643,0.037350108,
2260.549,127.3,1.915,192.1500276,0.037644977,
2264.194,128.1,1.931,192.459858,0.037959505,
2267.075,128.9,1.947,192.7047473,0.038274032,
2269.472,129.7,1.963,192.9084959,0.038588559,
2275.026,130.5,1.98,193.3805942,0.038922744,
2276.615,131.3,1.995,193.5156615,0.039217614,
2280.714,132.1,2.011,193.8640826,0.039532141,
2283.641,132.9,2.028,194.112882,0.039866326,
2286.142,133.7,2.043,194.3254707,0.040161195,
2290.419,134.5,2.06,194.6890221,0.04049538,
2292.582,135.3,2.076,194.8728803,0.040809908,
2295.907,136.1,2.092,195.1555102,0.041124435,
2299.278,136.9,2.108,195.4420502,0.041438962,
2301.588,137.7,2.124,195.6384037,0.041753489,
2305.714,138.5,2.141,195.9891198,0.042087674,
2307.696,139.3,2.156,196.1575928,0.042382544,
2310.969,140.1,2.172,196.4358026,0.042697071,
2315.11,140.9,2.188,196.7877938,0.043011598,
2316.814,141.7,2.204,196.9326363,0.043326125,
2320.471,142.5,2.221,197.2434868,0.043660311,
2322.974,143.3,2.237,197.4562455,0.043974838,
2325.606,144.1,2.252,197.6799694,0.044269707,
2330.049,144.9,2.268,198.057631,0.044584234,
2331.803,145.7,2.285,198.2067236,0.04491842,
2334.913,146.5,2.301,198.4710782,0.045232947,
2337.79,147.3,2.317,198.7156275,0.045547474,
2340.172,148.1,2.332,198.9181011,0.045842343,
2344.476,148.9,2.349,199.2839475,0.046176528,
2345.834,149.7,2.365,199.3993795,0.046491056,
2348.867,150.5,2.381,199.657189,0.046805583,
2352.073,151.3,2.397,199.9297038,0.04712011,
2354.425,152.1,2.413,200.1296273,0.047434637,
2358.901,152.9,2.43,200.5100939,0.047768822,
2360.058,153.7,2.445,200.6084406,0.048063692,
2362.775,154.5,2.46,200.8393897,0.048358561,
2366.421,155.3,2.477,201.1493051,0.048692746,
2368.184,156.1,2.494,201.2991627,0.049026931,
2372.369,156.9,2.509,201.654894,0.049321801,
2373.774,157.7,2.524,201.7743211,0.04961667,
2376.441,158.5,2.541,202.00102,0.049950855,
2379.899,159.3,2.557,202.2949552,0.050265382,
2381.46,160.1,2.573,202.4276425,0.05057991,
2385.369,160.9,2.589,202.7599133,0.050894437,
2387.214,161.7,2.605,202.916741,0.051208964,
2389.3,162.5,2.622,203.0940541,0.051543149,
2393.192,163.3,2.637,203.4248799,0.051838018,
2394.481,164.1,2.653,203.5344469,0.052152546,
2398.211,164.9,2.67,203.8515024,0.052486731,
2399.993,165.7,2.686,204.0029751,0.052801258,
2402.506,166.5,2.702,204.2165838,0.053115785,
2405.893,167.3,2.718,204.5044838,0.053430313,
2407.067,168.1,2.735,204.6042756,0.053764498,
2410.308,168.9,2.75,204.8797654,0.054059367,
2412.981,169.7,2.766,205.1069744,0.054373894,
2414.858,170.5,2.783,205.2665222,0.054708079,
2418.368,171.3,2.799,205.5648774,0.055022607,
2419.76,172.1,2.815,205.6831995,0.055337134,
2422.64,172.9,2.831,205.9280037,0.055651661,
2425.337,173.7,2.848,206.1572528,0.055985846,
2427.068,174.5,2.864,206.3043903,0.056300374,
2430.38,175.3,2.879,206.5859153,0.056595243,
2431.83,176.1,2.895,206.7091674,0.05690977,
2434.544,176.9,2.913,206.9398614,0.057263613,
2437.368,177.7,2.929,207.1799056,0.05757814,
2438.944,178.5,2.944,207.313868,0.05787301,
2442.446,179.3,2.961,207.6115432,0.058207195,
2443.69,180.1,2.977,207.7172851,0.058521722,
2445.651,180.9,2.994,207.883973,0.058855907,
2449.364,181.7,3.009,208.1995835,0.059150776,
2450.833,182.5,3.026,208.3244507,0.059484962,
2453.8,183.3,3.041,208.5766501,0.059779831,
2455.303,184.1,3.058,208.7044073,0.060114016,
2457.298,184.9,3.075,208.8739853,0.060448201,
2461.025,185.7,3.091,209.1907858,0.060762729,
2461.758,186.5,3.107,209.2530919,0.061077256,
2465.128,187.3,3.124,209.5395469,0.061411441,
2466.884,188.1,3.14,209.6888096,0.061725968,
2468.332,188.9,3.157,209.8118917,0.062060153,
2472.069,189.7,3.173,210.1295423,0.062374681,
2472.882,190.5,3.189,210.1986485,0.062689208,
2475.553,191.3,3.206,210.4256874,0.063023393,
2477.885,192.1,3.222,210.6239109,0.06333792,
2479.456,192.9,3.238,210.7574483,0.063652447,
2483.291,193.7,3.255,211.083429,0.063986633,
2484.058,194.5,3.271,211.1486251,0.06430116,
2486.81,195.3,3.288,211.3825492,0.064635345,
2488.477,196.1,3.305,211.5242467,0.06496953,
2489.972,196.9,3.321,211.6513239,0.065284057,
2493.553,197.7,3.337,211.9557142,0.065598585,
2494.778,198.5,3.354,212.059841,0.06593277,
2497.265,199.3,3.371,212.2712397,0.066266955,
2499.126,200.1,3.387,212.4294275,0.066581482,
2500.157,200.9,3.403,212.517064,0.066896009,
2503.772,201.7,3.42,212.8243444,0.067230195,
2505.129,202.5,3.436,212.9396914,0.067544722,
2507.899,203.3,3.453,213.1751456,0.067878907,
2509.707,204.1,3.47,213.3288283,0.068213092,
2510.784,204.9,3.486,213.4203749,0.068527619,
2513.922,205.7,3.503,213.6871095,0.068861805,
2515.083,206.5,3.519,213.7857963,0.069176332,
2516.855,207.3,3.536,213.9364189,0.069510517,
2519.841,208.1,3.553,214.1902333,0.069844702,
2520.759,208.9,3.57,214.2682647,0.070178887,
2524.021,209.7,3.586,214.5455395,0.070493415,
2524.86,210.5,3.603,214.6168558,0.0708276,
2526.946,211.3,3.62,214.7941689,0.071161785,
2529.882,212.1,3.637,215.0437333,0.07149597,
2530.481,212.9,3.653,215.0946492,0.071810497,
2532.917,213.7,3.67,215.3017128,0.072144683,
2534.614,214.5,3.686,215.4459603,0.07245921,
2536.274,215.3,3.704,215.5870628,0.072813053,
2539.416,216.1,3.721,215.8541374,0.073147238,
2540.105,216.9,3.737,215.9127035,0.073461765,
2542.454,217.7,3.753,216.112372,0.073776293,
2544.457,218.5,3.77,216.2826299,0.074110478,
2545.806,219.3,3.787,216.397297,0.074444663,
2548.182,220.1,3.804,216.5992605,0.074778848,
2549.548,220.9,3.822,216.7153725,0.075132691,
2551.189,221.7,3.838,216.85486,0.075447218,
2553.9,222.5,3.855,217.085299,0.075781404,
2554.366,223.3,3.872,217.1249097,0.076115589,
2557.56,224.1,3.889,217.3964044,0.076449774,
2558.515,224.9,3.906,217.4775809,0.076783959,
2560.082,225.7,3.922,217.6107782,0.077098486,
2563.104,226.5,3.94,217.8676527,0.077452329,
2563.676,227.3,3.957,217.9162735,0.077786515,
2566.047,228.1,3.974,218.1178121,0.0781207,
2567.204,228.9,3.991,218.2161588,0.078454885,
2568.859,229.7,4.008,218.3568362,0.07878907,
2572.024,230.5,4.025,218.625866,0.079123255,
2572.338,231.3,4.041,218.6525564,0.079437783,
2574.707,232.1,4.059,218.8539249,0.079791626,
2575.957,232.9,4.076,218.9601768,0.080125811,
2577.57,233.7,4.093,219.0972842,0.080459996,
2580.61,234.5,4.11,219.3556887,0.080794181,
2581.005,235.3,4.127,219.3892643,0.081128366,
2583.027,236.1,4.145,219.5611373,0.08148221,
2584.588,236.9,4.161,219.6938246,0.081796737,
2585.962,237.7,4.179,219.8106167,0.08215058,
2589.318,238.5,4.196,220.0958817,0.082484765,
2589.145,239.3,4.214,220.0811764,0.082838608,
2591.011,240.1,4.23,220.2397892,0.083153135,
2592.811,240.9,4.247,220.3927919,0.083487321,
2594.107,241.7,4.265,220.5029538,0.083841164,
2596.991,242.5,4.282,220.7480981,0.084175349,
2597.467,243.3,4.299,220.7885588,0.084509534,
2598.827,244.1,4.316,220.9041608,0.084843719,
2601.556,244.9,4.334,221.1361299,0.085197562,
2602.25,245.7,4.351,221.1951209,0.085531748,
2604.767,246.5,4.368,221.4090697,0.085865933,
2605.275,247.3,4.385,221.4522504,0.086200118,
2606.856,248.1,4.403,221.5866378,0.086553961,
2609.605,248.9,4.42,221.8203069,0.086888146,
2610.193,249.7,4.437,221.8702877,0.087222331,
2612.685,250.5,4.455,222.0821114,0.087576175,
2613.551,251.3,4.473,222.1557227,0.087930018,
2614.377,252.1,4.49,222.225934,0.088264203,
2616.569,252.9,4.507,222.4122572,0.088598388,
2617.444,253.7,4.525,222.4866335,0.088952231,
2619.715,254.5,4.543,222.6796719,0.089306074,
2621.299,255.3,4.56,222.8143143,0.089640259,
2622.034,256.1,4.577,222.8767903,0.089974445,
2624.243,256.9,4.594,223.0645586,0.09030863,
2625.135,257.7,4.612,223.14038,0.090662473,
2627.292,258.5,4.63,223.3237282,0.091016316,
2628.561,259.3,4.648,223.4315951,0.091370159,
2629.468,260.1,4.665,223.5086914,0.091704344,
2631.433,260.9,4.683,223.6757193,0.092058188,
2632.227,261.7,4.701,223.7432105,0.092412031,
2634.154,262.5,4.719,223.9070084,0.092765874,
2635.616,263.3,4.736,224.0312805,0.093100059,
2636.552,264.1,4.753,224.1108419,0.093434244,
2638.373,264.9,4.771,224.2656296,0.093788087,
2639.39,265.7,4.789,224.3520762,0.09414193,
2641.383,266.5,4.807,224.5214841,0.094495774,
2642.687,267.3,4.825,224.6323261,0.094849617,
2643.147,268.1,4.843,224.6714267,0.09520346,
2645.469,268.9,4.861,224.8688002,0.095557303,
2646.235,269.7,4.878,224.9339113,0.095891488,
2648.162,270.5,4.896,225.0977092,0.096245331,
2649.681,271.3,4.914,225.2268265,0.096599174,
2649.979,272.1,4.932,225.2521569,0.096953017,
2651.754,272.9,4.948,225.4030346,0.097267545,
2652.794,273.7,4.966,225.4914361,0.097621388,
2655.205,274.5,4.984,225.6963747,0.097975231,
2656.4,275.3,5.002,225.7979515,0.098329074,
2656.914,276.1,5.02,225.8416422,0.098682917,
2658.49,276.9,5.038,225.9756046,0.09903676,
2659.399,277.7,5.057,226.0528709,0.099410261,
2660.755,278.5,5.075,226.1681329,0.099764105,
2662.704,279.3,5.093,226.3338008,0.100117948,
2662.981,280.1,5.111,226.3573463,0.100471791,
2665.117,280.9,5.129,226.5389094,0.100825634,
2666.134,281.7,5.145,226.6253559,0.101140161,
2667.205,282.5,5.165,226.7163925,0.10153332,
2669.387,283.3,5.182,226.9018658,0.101867505,
2669.57,284.1,5.199,226.9174211,0.102201691,
2671.24,284.9,5.218,227.0593735,0.102575192,
2672.494,285.7,5.236,227.1659654,0.102929035,
2672.851,286.5,5.254,227.1963109,0.103282878,
2675.846,287.3,5.272,227.4508904,0.103636721,
2675.559,288.1,5.29,227.426495,0.103990564,
2676.9,288.9,5.308,227.540482,0.104344407,
2678.702,289.7,5.326,227.6936546,0.10469825,
2679.012,290.5,5.344,227.7200051,0.105052094,
2681.744,291.3,5.363,227.9522292,0.105425595,
2681.674,292.1,5.381,227.9462791,0.105779438,
2682.778,292.9,5.4,228.0401207,0.106152939,
2684.739,293.7,5.418,228.2068086,0.106506782,
2684.575,294.5,5.437,228.1928684,0.106880283,
2687.31,295.3,5.455,228.4253474,0.107234126,
2687.673,296.1,5.474,228.456203,0.107607627,
2688.498,296.9,5.492,228.5263292,0.10796147,
2690.793,297.7,5.511,228.7214076,0.108334971,
2690.378,298.5,5.529,228.686132,0.108688815,
2692.793,299.3,5.548,228.8914106,0.109062316,
2693.562,300.1,5.567,228.9567767,0.109435817,
2693.642,300.9,5.585,228.9635769,0.10978966,
2695.909,301.7,5.603,229.1562752,0.110143503,
2696.094,302.5,5.622,229.1720005,0.110517004,
2697.857,303.3,5.641,229.3218581,0.110890505,
2699.292,304.1,5.66,229.4438353,0.111264006,
2699.056,304.9,5.678,229.4237749,0.111617849,
2701.388,305.7,5.697,229.6219984,0.111991351,
2701.181,306.5,5.716,229.6044031,0.112364852,
2702.643,307.3,5.734,229.7286753,0.112718695,
2704.563,308.1,5.753,229.8918781,0.113092196,
2704.502,308.9,5.771,229.886693,0.113446039,
2706.625,309.7,5.79,230.0671512,0.11381954,
2707.069,310.5,5.809,230.1048918,0.114193041,
2707.639,311.3,5.828,230.1533427,0.114566542,
2710.035,312.1,5.847,230.3570062,0.114940043,
2709.659,312.9,5.866,230.3250457,0.115313544,
2711.435,313.7,5.884,230.4760083,0.115667387,
2711.802,314.5,5.904,230.5072039,0.116060546,
2712.559,315.3,5.922,230.57155,0.11641439,
2715.006,316.1,5.941,230.7795486,0.116787891,
2714.611,316.9,5.96,230.7459731,0.117161392,
2716.352,317.7,5.979,230.8939606,0.117534893,
2717.212,318.5,5.999,230.9670619,0.117928052,
2717.479,319.3,6.017,230.9897573,0.118281895,
2719.8,320.1,6.036,231.1870458,0.118655396,
2719.711,320.9,6.055,231.1794806,0.119028897,
2720.844,321.7,6.075,231.2757873,0.119422056,
2722.396,322.5,6.094,231.4077096,0.119795557,
2722.314,323.3,6.113,231.4007395,0.120169058,
2724.386,324.1,6.132,231.5768626,0.120542559,
2723.915,324.9,6.151,231.5368269,0.120916061,
2725.512,325.7,6.17,231.6725743,0.121289562,
2726.741,326.5,6.189,231.7770411,0.121663063,
2726.998,327.3,6.209,231.7988865,0.122056222,
2729.552,328.1,6.228,232.0159803,0.122429723,
2729.05,328.9,6.247,231.9733095,0.122803224,
2729.658,329.7,6.266,232.0249904,0.123176725,
2731.597,330.5,6.286,232.1898083,0.123569884,
2731.553,331.3,6.305,232.1860683,0.123943385,
2733.72,332.1,6.324,232.3702665,0.124316886,
2733.152,332.9,6.343,232.3219856,0.124690387,
2734.07,333.7,6.363,232.400017,0.125083546,
2735.248,334.5,6.382,232.5001488,0.125457047,
2735.977,335.3,6.402,232.5621148,0.125850206,
2738.315,336.1,6.421,232.7608483,0.126223707,
2737.945,336.9,6.44,232.7293978,0.126597209,
2738.595,337.7,6.46,232.7846487,0.126990368,
2740.058,338.5,6.48,232.9090059,0.127383527,
2740.401,339.3,6.5,232.9381614,0.127776686,
2742.067,340.1,6.519,233.0797739,0.128150187,
2741.871,340.9,6.538,233.0631136,0.128523688,
2742.805,341.7,6.558,233.142505,0.128916847,
2744.147,342.5,6.577,233.256577,0.129290348,
2744.44,343.3,6.597,233.2814824,0.129683507,
2745.89,344.1,6.617,233.4047346,0.130076666,
2745.365,344.9,6.637,233.3601088,0.130469825,
2746.94,345.7,6.656,233.4939861,0.130843326,
2748.282,346.5,6.676,233.6080581,0.131236485,
2748.26,347.3,6.695,233.6061881,0.131609986,
2750.475,348.1,6.715,233.7944664,0.132003145,
2749.828,348.9,6.735,233.7394704,0.132396304,
2750.694,349.7,6.754,233.8130817,0.132769805,
2752.141,350.5,6.774,233.9360789,0.133162964,
2751.831,351.3,6.794,233.9097284,0.133556123,
2753.897,352.1,6.814,234.0853415,0.133949282,
2753.794,352.9,6.834,234.0765863,0.134342442,
2754.281,353.7,6.854,234.1179821,0.134735601,
2756.396,354.5,6.874,234.2977602,0.13512876,
2755.642,355.3,6.894,234.2336691,0.135521919,
2756.962,356.1,6.914,234.3458711,0.135915078,
2757.757,356.9,6.934,234.4134472,0.136308237,
2757.897,357.7,6.954,234.4253474,0.136701396,
2759.384,358.5,6.974,234.5517447,0.137094555,
2759.002,359.3,6.994,234.5192741,0.137487714,
2760.043,360.1,7.015,234.6077606,0.137900531,
2761.684,360.9,7.035,234.7472481,0.13829369,
2761.16,361.7,7.055,234.7027073,0.138686849,
2762.83,362.5,7.075,234.8446598,0.139080008,
2762.837,363.3,7.095,234.8452548,0.139473167,
2763.414,364.1,7.116,234.8943007,0.139885984,
2765.391,364.9,7.136,235.0623486,0.140279143,
2764.573,365.7,7.156,234.9928174,0.140672302,
2765.596,366.5,7.176,235.0797739,0.141065461,
2766.494,367.3,7.197,235.1561052,0.141478278,
2766.433,368.1,7.217,235.1509201,0.141871437,
2768.32,368.9,7.237,235.3113179,0.142264596,
2768.212,369.7,7.258,235.3021378,0.142677413,
2769.149,370.5,7.278,235.3817842,0.143070572,
2770.014,371.3,7.298,235.4553105,0.143463731,
2769.595,372.1,7.319,235.4196948,0.143876548,
2771.486,372.9,7.34,235.5804327,0.144289365,
2771.005,373.7,7.36,235.5395469,0.144682524,
2772.096,374.5,7.38,235.6322836,0.145075683,
2773.477,375.3,7.401,235.7496706,0.1454885,
2772.686,376.1,7.421,235.6824344,0.145881659,
2774.171,376.9,7.442,235.8086617,0.146294476,
2774.594,377.7,7.462,235.8446173,0.146687635,
2774.843,378.5,7.483,235.8657827,0.147100452,
2776.727,379.3,7.504,236.0259255,0.147513269,
2775.931,380.1,7.525,235.9582643,0.147926086,
2776.822,380.9,7.545,236.0340006,0.148319245,
2777.52,381.7,7.566,236.0933316,0.148732062,
2777.79,382.5,7.587,236.116282,0.149144879,
2779.612,383.3,7.608,236.2711547,0.149557696,
2778.535,384.1,7.629,236.1796081,0.149970513,
2779.866,384.9,7.65,236.2927451,0.15038333,
2780.539,385.7,7.67,236.3499511,0.150776489,
2780.668,386.5,7.691,236.3609163,0.151189306,
2782.082,387.3,7.712,236.4811084,0.151602123,
2781.421,388.1,7.733,236.4249224,0.15201494,
2782.192,388.9,7.754,236.4904586,0.152427757,
2783.45,389.7,7.774,236.5973905,0.152820916,
2783.037,390.5,7.795,236.5622848,0.153233733,
2784.534,391.3,7.817,236.6895321,0.153666208,
2784.012,392.1,7.838,236.6451613,0.154079025,
2784.93,392.9,7.859,236.7231927,0.154491842,
2786.437,393.7,7.88,236.8512899,0.154904659,
2785.886,394.5,7.901,236.8044541,0.155317476,
2787.005,395.3,7.923,236.8995707,0.155749951,
2786.363,396.1,7.944,236.8449998,0.156162768,
2786.885,396.9,7.964,236.8893706,0.156555927,
2788.986,397.7,7.985,237.0679587,0.156968744,
2788.219,398.5,8.006,237.0027625,0.157381561,
2789.384,399.3,8.027,237.1017893,0.157794378,
2789.306,400.1,8.049,237.0951592,0.158226853,
2789.886,400.9,8.07,237.14446,0.15863967,
2791.231,401.7,8.091,237.258787,0.159052487,
2790.417,402.5,8.112,237.1895958,0.159465304,
2791.586,403.3,8.134,237.2889626,0.159897779,
2791.722,404.1,8.155,237.3005228,0.160310596,
2792.011,404.9,8.176,237.3250882,0.160723413,
2793.767,405.7,8.198,237.4743508,0.161155888,
2792.417,406.5,8.219,237.3595988,0.161568705,
2794.1,407.3,8.241,237.5026563,0.162001179,
2794.202,408.1,8.262,237.5113264,0.162413996,
2794.463,408.9,8.283,237.5335118,0.162826813,
2795.992,409.7,8.305,237.6634791,0.163259288,
2794.93,410.5,8.327,237.5732075,0.163691763,
2796.1,411.3,8.348,237.6726593,0.16410458,
2796.143,412.1,8.37,237.6763143,0.164537055,
2795.96,412.9,8.391,237.6607591,0.164949872,
2798.446,413.7,8.412,237.8720728,0.165362689,
2797.342,414.5,8.434,237.7782311,0.165795164,
2798.509,415.3,8.456,237.8774279,0.166227639,
2798.121,416.1,8.477,237.8444473,0.166640456,
2797.765,416.9,8.499,237.8141867,0.167072931,
2800.174,417.7,8.521,238.0189553,0.167505406,
2799.476,418.5,8.542,237.9596243,0.167918223,
2800.161,419.3,8.564,238.0178503,0.168350698,
2800.369,420.1,8.587,238.0355306,0.168802831,
2800.208,420.9,8.608,238.0218454,0.169215648,
2801.699,421.7,8.63,238.1485826,0.169648123,
2800.735,422.5,8.651,238.0666412,0.17006094,
2801.776,423.3,8.673,238.1551277,0.170493415,
2802.025,424.1,8.695,238.1762931,0.17092589,
2801.724,424.9,8.718,238.1507076,0.171378022,
2803.747,425.7,8.739,238.3226656,0.171790839,
2802.898,426.5,8.761,238.2504994,0.172223314,
2803.424,427.3,8.783,238.2952102,0.172655789,
2804.002,428.1,8.806,238.344341,0.173107922,
2803.469,428.9,8.828,238.2990352,0.173540397,
2805.147,429.7,8.85,238.4416677,0.173972872,
2804.316,430.5,8.872,238.3710315,0.174405347,
2804.799,431.3,8.894,238.4120872,0.174837822,
2805.927,432.1,8.916,238.5079689,0.175270297,
2805.542,432.9,8.939,238.4752433,0.17572243,
2806.427,433.7,8.961,238.5504696,0.176154905,
2806.299,434.5,8.984,238.5395894,0.176607038,
2805.907,435.3,9.006,238.5062689,0.177039512,
2807.088,436.1,9.028,238.6066556,0.177471987,
2806.7,436.9,9.051,238.573675,0.17792412,
2807.108,437.7,9.073,238.6083556,0.178356595,
2807.928,438.5,9.096,238.6780569,0.178808728,
2807.609,439.3,9.118,238.6509414,0.179241203,
2808.54,440.1,9.14,238.7300778,0.179673678,
2808.261,440.9,9.162,238.7063624,0.180106153,
2808.496,441.7,9.185,238.7263377,0.180558286,
2809.682,442.5,9.208,238.8271495,0.181010419,
2808.684,443.3,9.23,238.742318,0.181442894,
2809.262,444.1,9.253,238.7914489,0.181895027,
2809.605,444.9,9.276,238.8206044,0.182347159,
2809.567,445.7,9.298,238.8173743,0.182779634,
2811.316,446.5,9.322,238.9660419,0.183251425,
2809.744,447.3,9.344,238.8324196,0.1836839,
2810.607,448.1,9.367,238.9057759,0.184136033,
2810.971,448.9,9.39,238.9367164,0.184588166,
2810.522,449.7,9.412,238.8985507,0.185020641,
2812.259,450.5,9.435,239.0461983,0.185472774,
2810.867,451.3,9.458,238.9278762,0.185924907,
2811.589,452.1,9.48,238.9892473,0.186357382,
2812.138,452.9,9.504,239.0359131,0.186829172,
2811.509,453.7,9.526,238.9824472,0.187261647,
2813.31,454.5,9.549,239.1355349,0.18771378,
2812.341,455.3,9.572,239.0531684,0.188165913,
2812.491,456.1,9.594,239.0659187,0.188598388,
2813.01,456.9,9.618,239.1100344,0.189070179,
2812.28,457.7,9.641,239.0479833,0.189522312,
2814.009,458.5,9.664,239.1949509,0.189974445,
2812.828,459.3,9.687,239.0945642,0.190426578,
2813.448,460.1,9.71,239.1472651,0.19087871,
2813.847,460.9,9.734,239.1811807,0.191350501,
2813.115,461.7,9.758,239.1189596,0.191822292,
2814.999,462.5,9.781,239.2791024,0.192274425,
2813.663,463.3,9.804,239.1655404,0.192726558,
2813.949,464.1,9.826,239.1898508,0.193159033,
2814.778,464.9,9.85,239.2603171,0.193630824,
2813.958,465.7,9.874,239.1906158,0.194102615,
2815.383,466.5,9.897,239.311743,0.194554747,
2814.205,467.3,9.921,239.2116112,0.195026538,
2814.028,468.1,9.944,239.1965659,0.195478671,
2815.324,468.9,9.968,239.3067279,0.195950462,
2814.383,469.7,9.991,239.2267415,0.196402595,
2815.498,470.5,10.015,239.3215181,0.196874386,
2814.987,471.3,10.038,239.2780824,0.197326519,
2814.517,472.1,10.062,239.2381317,0.197798309,
2816.089,472.9,10.085,239.371754,0.198250442,
2814.775,473.7,10.109,239.2600621,0.198722233,
2815.757,474.5,10.133,239.3435335,0.199194024,
2815.134,475.3,10.157,239.2905776,0.199665815,
2814.998,476.1,10.181,239.2790174,0.200137606,
2816.147,476.9,10.204,239.3766841,0.200589739,
2814.683,477.7,10.228,239.2522419,0.201061529,
2815.221,478.5,10.252,239.2979727,0.20153332,
2815.46,479.3,10.275,239.3182881,0.201985453,
2814.587,480.1,10.3,239.2440818,0.202476902,
2816.139,480.9,10.324,239.3760041,0.202948693,
2814.479,481.7,10.348,239.2349016,0.203420484,
2815.407,482.5,10.371,239.313783,0.203872616,
2814.831,483.3,10.395,239.2648221,0.204344407,
2814.039,484.1,10.419,239.197501,0.204816198,
2815.395,484.9,10.444,239.312763,0.205307647,
2813.869,485.7,10.468,239.1830507,0.205779438,
2814.4,486.5,10.492,239.2281865,0.206251229,
2814.061,487.3,10.517,239.199371,0.206742677,
2813.051,488.1,10.541,239.1135195,0.207214468,
2813.464,488.9,10.565,239.1486251,0.207686259,
2812.734,489.7,10.589,239.086574,0.20815805,
2812.833,490.5,10.614,239.0949892,0.208649499,
2812.807,491.3,10.638,239.0927791,0.20912129,
2811.263,492.1,10.663,238.9615368,0.209612738,
2811.731,492.9,10.688,239.0013175,0.210104187,
2810.219,493.7,10.712,238.8727953,0.210575978,
2810.073,494.5,10.737,238.8603851,0.211067427,
2810.434,495.3,10.762,238.8910706,0.211558876,
2808.515,496.1,10.787,238.7279527,0.212050324,
2808.359,496.9,10.812,238.7146925,0.212541773,
2807.293,497.7,10.837,238.6240809,0.213033222,
2805.67,498.5,10.863,238.4861235,0.213544329,
2806.246,499.3,10.888,238.5350844,0.214035777,
2803.872,500.1,10.913,238.3332908,0.214527226,
2803.167,500.9,10.937,238.2733648,0.214999017,
2801.242,501.7,10.963,238.1097369,0.215510124,
2799.093,502.5,10.988,237.9270687,0.216001573,
2799.301,503.3,11.014,237.944749,0.216512679,
2796.06,504.1,11.039,237.6692592,0.217004128,
2793.459,504.9,11.064,237.4481703,0.217495577,
2791.268,505.7,11.09,237.2619321,0.218006684,
2786.596,506.5,11.116,236.8648051,0.21851779,
2784.427,507.3,11.141,236.6804369,0.219009239,
2778.309,508.1,11.168,236.1603978,0.219540004,
2771.25,508.9,11.195,235.5603723,0.220070769,
2764.336,509.7,11.221,234.972672,0.220581875,
2750.767,510.5,11.248,233.8192868,0.22111264,
2736.003,511.3,11.276,232.5643249,0.221663063,
2716.436,512.1,11.303,230.9011008,0.222193827,
2688.438,512.9,11.331,228.5212291,0.22274425,
2654.994,513.7,11.361,225.6784394,0.223333989,
2609.368,514.5,11.392,221.8001615,0.223943385,
2546.231,515.3,11.426,216.4334226,0.224611755,
2464.205,516.1,11.461,209.4610906,0.225299784,
2323.21,516.9,11.503,197.4763058,0.226125418,
-210.166,517.02,11.992,-17.86442263,0.235738156,